<?xml version="1.0"?>
<robot name="Puzzlebot_Jetson_Lidar_Ed">

  <material name="green">
    <color rgba="0.0 1.0 0.0 1.0"/>
  </material>
  <material name="black">
    <color rgba="0.0 0.0 0.0 1.0"/>
  </material>

  <link name="base_footprint"/>

  <link name="base_link">
    <visual>
      <origin xyz="0 0 0" rpy="0 0 0"/>
      <geometry>
        <mesh filename="package://puzzlebot_description/meshes/Puzzlebot_Jetson_Lidar_Edition_Base.stl" scale="1 1 1"/>
      </geometry>
      <material name="green"/>
    </visual>
  </link>

  <link name="wheel_r_link">
    <visual>
      <origin xyz="0 0 0" rpy="-1.5708 0 0"/>
      <geometry>
        <mesh filename="package://puzzlebot_description/meshes/Puzzlebot_Wheel.stl" scale="1 1 1"/>
      </geometry>
      <material name="green"/>
    </visual>
  </link>

  <link name="wheel_l_link">
    <visual>
      <origin xyz="0 0 0" rpy="1.5708 0 0"/>
      <geometry>
        <mesh filename="package://puzzlebot_description/meshes/Puzzlebot_Wheel.stl" scale="1 1 1"/>
      </geometry>
      <material name="green"/>
    </visual>
  </link>
   
  <link name="caster_link">
    <visual>
      <origin xyz="0 0 0" rpy="0 0 0"/>
      <geometry>
        <mesh filename="package://puzzlebot_description/meshes/Puzzlebot_Caster_Wheel.stl" scale="1 1 1"/>
      </geometry>
      <material name="green"/>
    </visual>
  </link>

  <link name="laser_link">
    <visual>
      <origin xyz="0 0 0" rpy="0 0 0"/>
      <geometry>
        <cylinder radius="0.03" length="0.04"/>
      </geometry>
      <material name="black"/>
    </visual>
  </link>

  <joint name="base_link_joint" type="fixed">
    <parent link="base_footprint"/>
    <child link="base_link"/>
    <origin xyz="0.0 0.0 0.05" rpy="0 0 0"/>
  </joint>

  <joint name="wheel_r_joint" type="continuous">
    <parent link="base_link"/>
    <child link="wheel_r_link"/>
    <origin xyz="0.052 -0.095 -0.0025" rpy="0 0 0"/>
    <axis xyz="0 1 0"/>
  </joint>

  <joint name="wheel_l_joint" type="continuous">
    <parent link="base_link"/>
    <child link="wheel_l_link"/>
    <origin xyz="0.052 0.095 -0.0025" rpy="0 0 0"/>
    <axis xyz="0 1 0"/>
  </joint>

  <joint name="caster_joint" type="fixed">
    <parent link="base_link"/>
    <child link="caster_link"/>
    <origin xyz="-0.095 0.0 -0.043" rpy="0 0 0"/>
  </joint>

  <joint name="laser_joint" type="fixed">
    <parent link="base_link"/>
    <child link="laser_link"/>
    <origin xyz="0.0 0.0 0.1" rpy="0 0 0"/> </joint>

</robot>